<?xml version="1.0"?>

<robot xmlns:sensor="http://playerstage.sourceforge.net/gazebo/xmlschema/#sensor"
       xmlns:controller="http://playerstage.sourceforge.net/gazebo/xmlschema/#controller"
       xmlns:interface="http://playerstage.sourceforge.net/gazebo/xmlschema/#interface"
       xmlns:xacro="http://ros.org/wiki/xacro">

  <!-- <include filename="$(find aisoy_description)/urdf/eyebrow/eyebrow.gazebo.xacro" /> -->
  <include filename="$(find aisoy_description)/urdf/eyebrow/eyebrow.transmission.xacro" />
  <property name="M_PI" value="3.1415926535897931" />

  <xacro:macro name="aisoy_eyebrow" params="name side reflect parent">

		<link name="${side}_${name}_link">
		  <inertial>
		    <mass value="0.0044168" />
		    <origin xyz="0.0014088 0.0043205 0.0030777" />
		    <inertia ixx="0.0000002" ixy="0.0" ixz="0.0"
		      iyy="0.0" iyz="0.0" izz="0.0000002" />
		  </inertial>

		  <visual>
				<origin xyz="0.01 ${-reflect*0.014} -0.208" rpy="0 0 0" /> 
		    <geometry>
		      <mesh filename="package://aisoy_description/meshes/eyebrow/eyebrow_${side}.dae"/>
		    </geometry>
		  </visual>

		  <collision>
		    <origin xyz="0 0 0" rpy="0 0 0" />
		    <geometry>
		      <box size="0.005 0.015 0.005" />
		    </geometry>
		  </collision>
		</link> 

		<joint name="${side}_${name}_joint" type="revolute">
		  <origin xyz="0.03 ${reflect*0.012} 0.0725" rpy="0 0 0" />
		  <axis xyz="${reflect} 0 0"/>   
		  <limit effort="10.0" lower="${M_PI/-6}" upper="${M_PI/8}" velocity="${M_PI}"/>   
		  <calibration rising="0.0"/>   
		  <parent link="${parent}"/>
		  <child link="${side}_${name}_link" />
		</joint>

		  <!-- extensions -->
		<xacro:aisoy_eyebrow_transmission name="${name}" side="${side}" />  

  </xacro:macro>

</robot>
