<?xml version="1.0"?>

<robot name="aisoy"  
       xmlns:xacro="http://ros.org/wiki/xacro">

  <property name="M_PI" value="3.14159"/>

  <link name="base_link">
    <inertial>
      <mass value="1.1242672" />
      <origin xyz="-0.0332797 0.0000456 0.0375629" />
      <inertia ixx="0.0032602" ixy="0.0000001" ixz="-0.0001248"
        iyy="0.0033958" iyz="0.0000002" izz="0.0039815" />
    </inertial>

    <visual>
      <origin xyz="0 0 0" rpy="0 0 0" />
      <geometry>
        <mesh filename="package://aisoy_description/meshes/01_aisoy1_base.dae"/>
      </geometry>
    </visual>

    <collision>
      <origin xyz="-0.0332797 0.0 0.0605" rpy="0 0 0" />
      <geometry>
        <cylinder length="0.121" radius="0.06"/>
      </geometry>
    </collision>
  </link>   
 
  <joint name="base_head_joint" type="revolute">
    <origin xyz="-0.043 0.0 0.121" rpy="0 0 0" />
    <axis xyz="0 0 1"/>   
    <limit effort="10.0" lower="${M_PI/-2}" upper="${M_PI/2}" velocity="${M_PI}"/>   
    <calibration rising="0.0"/>   
    <parent link="base_link"/>
    <child link="head_link" />
  </joint>

  <link name="head_link">
    <inertial>
      <mass value="0.3249771" />
      <origin xyz="-0.0016012 0.0003076 0.0592513" />
      <inertia ixx="0.0004418" ixy="-0.0000033" ixz="-0.0000301"
        iyy="0.0003612" iyz="-0.0000008" izz="0.0004281" />
    </inertial>

    <visual>
      <origin xyz="0.043 0 -0.121" rpy="0 0 0" />
      <geometry>
        <mesh filename="package://aisoy_description/meshes/02_aisoy1_head.dae"/>
      </geometry>
    </visual>

    <collision>
      <origin xyz="-0.0 0.0 0.047" rpy="0 0 0" />
      <geometry>
        <sphere radius="0.047"/>
      </geometry>
    </collision>

  </link>    

  <joint name="head_eyebrow_l_joint" type="revolute">
    <origin xyz="0.030 0.012 0.08681" rpy="0 0 0" />
    <axis xyz="1 0 0"/>   
    <limit effort="10.0" lower="${M_PI/-6}" upper="${M_PI/8}" velocity="${M_PI}"/>   
    <calibration rising="0.0"/>   
    <parent link="head_link"/>
    <child link="eyebrow_l_link" />
  </joint>

  <link name="eyebrow_l_link">
    <inertial>
      <mass value="0.0044168" />
      <origin xyz="0.0014088 0.0043205 0.0030777" />
      <inertia ixx="0.0000002" ixy="0.0" ixz="0.0"
        iyy="0.0" iyz="0.0" izz="0.0000002" />
    </inertial>

    <visual>
      <origin xyz="0.013 -0.012 -0.20781" rpy="0 0 0" />
      <geometry>
        <mesh filename="package://aisoy_description/meshes/03_aisoy1_eyebrows_l.dae"/>
      </geometry>
    </visual>

    <collision>
      <origin xyz="-0.0 0.005 0.002" rpy="0 0 0" />
      <geometry>
        <box size="0.004 0.023 0.004" />
      </geometry>
    </collision>

  </link> 

  <joint name="head_eyebrow_r_joint" type="revolute">
    <origin xyz="0.030 -0.012 0.08681" rpy="0 0 0" />
    <axis xyz="-1 0 0"/>   
    <limit effort="10.0" lower="${M_PI/-6}" upper="${M_PI/8}" velocity="${M_PI}"/>   
    <calibration rising="0.0"/>   
    <parent link="head_link"/>
    <child link="eyebrow_r_link" />
  </joint>

  <link name="eyebrow_r_link">
    <inertial>
      <mass value="0.0044168" />
      <origin xyz="0.0014088 -0.0043205 0.0030777" />
      <inertia ixx="0.0000002" ixy="0.0" ixz="0.0"
        iyy="0.0" iyz="0.0" izz="0.0000002" />
    </inertial>

    <visual>
      <origin xyz="0.013 0.012 -0.20781" rpy="0 0 0" />
      <geometry>
        <mesh filename="package://aisoy_description/meshes/03_aisoy1_eyebrows_r.dae"/>
      </geometry>
    </visual>

    <collision>
      <origin xyz="-0.0 -0.005 0.002" rpy="0 0 0" />
      <geometry>
        <box size="0.004 0.023 0.004" />
      </geometry>
    </collision>

  </link> 

</robot>
