<?xml version="1.0"?>

<robot xmlns:sensor="http://playerstage.sourceforge.net/gazebo/xmlschema/#sensor"
       xmlns:controller="http://playerstage.sourceforge.net/gazebo/xmlschema/#controller"
       xmlns:interface="http://playerstage.sourceforge.net/gazebo/xmlschema/#interface"
       xmlns:xacro="http://ros.org/wiki/xacro">

  <!-- <include filename="$(find aisoy_description)/urdf/head/head.gazebo.xacro" /> -->
  <include filename="$(find aisoy_description)/urdf/head/head.transmission.xacro" />
  <property name="M_PI" value="3.1415926535897931" />

  <xacro:macro name="aisoy_head_pan" params="name parent">
		<link name="${name}_link">
 			<inertial>
				<mass value="0.16" /> 
        <origin xyz="0.010907 0.031693 0.090507" rpy="0 0 0" />
        <inertia ixx="0.032497592"  ixy="0.00063604088"  ixz="0.0025851534"
                 iyy="0.046545627"  iyz="-0.0024534295"  izz="0.057652724" />
		  </inertial>
		  <visual>
				<origin xyz="0 0 0" />
		    <geometry>
					<box size="0.001 0.001 0.001"/>
		    </geometry>
		  </visual>
		  <collision>
				<origin xyz="0 0 0" />
		    <geometry>
					<box size="0.001 0.001 0.001"/>
		    </geometry>
		  </collision>
    </link>

		<joint name="${name}_joint" type="revolute">
      <axis xyz="0 0 1" />
      <limit lower="${-M_PI/2}" upper="${M_PI/2}" effort="2.645" velocity="6" /> 
      <safety_controller k_velocity="1.5" soft_lower_limit="${-M_PI/2+0.15}" soft_upper_limit="${M_PI/2-0.15}" k_position="100" />
      <calibration rising="0.0" />
      <dynamics damping="0.5" />
			<!-- <origin xyz="-0.060 0.0 0.135" />  -->
			<origin xyz="-0.040 0.0 0.1325" />
      <parent link="${parent}"/>
      <child link="${name}_link"/>
    </joint>

    <!-- extensions -->
    <xacro:aisoy_head_pan_transmission name="head_pan" />  

  </xacro:macro>

  <xacro:macro name="aisoy_head_tilt" params="name parent">

    <link name="${name}_link">
			<inertial>
				<mass value="0.16" /> <!-- mass/cog/moi updated per 100505_link_data.xls -->
        <origin xyz="0.001716 -0.019556 0.055002" rpy="0 0 0" />
        <inertia ixx="0.024223222"  ixy="0.00062063507"  ixz="-0.000096909696"
                 iyy="0.054723086"  iyz="0.00279702400"
                 izz="0.067306377" />
		  </inertial>
      <visual>
				<origin xyz="0.040 0.0 -0.135" rpy="0 0 0" /> <!-- por el .dae, probar .stl -->
		    <geometry>
		       <mesh filename="package://aisoy_description/meshes/head/head.dae"/>  
		    </geometry>
      </visual>
      <collision>
				<origin xyz="0 0 0" rpy="0 0 0" />
		    <geometry>
         	<sphere radius="0.047"/> 
        </geometry>
      </collision>
    </link>

		<joint name="${name}_joint" type="revolute">
			<origin xyz="0 0 0.002" /> 
      <axis xyz="0 1 0" />
      <limit lower="${-M_PI/6}" upper="${M_PI/6}" effort="18" velocity="5" />
      <safety_controller k_velocity="3.0" soft_lower_limit="${-M_PI/6 + 0.1}" soft_upper_limit="${M_PI/6 - 0.1}" k_position="100" />
      <calibration falling="${0.0+cal_head_tilt_flag}" />
      <dynamics damping="10.0" />
      <parent link="head_pan_link"/>
      <child link="head_tilt_link"/>
    </joint>

    <!-- extensions -->
		<xacro:aisoy_head_tilt_transmission name="head_tilt" /> 

  </xacro:macro>

  <xacro:macro name="aisoy_head" params="name parent">
    <xacro:aisoy_head_pan name="${name}_pan" parent="${parent}" />
    <xacro:aisoy_head_tilt name="${name}_tilt" parent="${name}_pan_link" /> 

    <!-- extensions 
    <xacro:aisoy_head_gazebo name="${name}" />  -->
    
  </xacro:macro>

</robot>
